Workbook

Sheet Data Dictionary
A1: Heart Disease Dataset — Data Dictionary
A2: Source file: health_data.xls (actually a comma-separated text file). 920 records × 15 fields across 4 sites. Blank cells = missing in source. Statistics are live formulas on the Data sheet.
A4: Field | B4: Name | C4: Description | D4: Type | E4: Unit | F4: Valid Codes | G4: Non-missing | H4: Missing | I4: % Missing | J4: Min | K4: Max | L4: Mean
A5: age | B5: Age | C5: Age of patient | D5: Continuous | E5: years | F5: — | G5: =COUNTA(Data!B2:B921) -> 920 | H5: =COUNTBLANK(Data!B2:B921) -> 0 | I5: =H5/920 -> 0 | J5: =MIN(Data!B2:B921) -> 28 | K5: =MAX(Data!B2:B921) -> 77 | L5: =AVERAGE(Data!B2:B921) -> 53.51087
A6: sex | B6: Sex | C6: Sex | D6: Binary | E6: — | F6: 0 = Female; 1 = Male | G6: =COUNTA(Data!C2:C921) -> 920 | H6: =COUNTBLANK(Data!C2:C921) -> 0 | I6: =H6/920 -> 0 | J6: =MIN(Data!C2:C921) -> 0 | K6: =MAX(Data!C2:C921) -> 1 | L6: =AVERAGE(Data!C2:C921) -> 0.78913043
A7: cp | B7: Chest Pain Type | C7: Chest pain type | D7: Categorical | E7: — | F7: 1 = Typical angina; 2 = Atypical angina; 3 = Non-anginal pain; 4 = Asymptomatic | G7: =COUNTA(Data!D2:D921) -> 920 | H7: =COUNTBLANK(Data!D2:D921) -> 0 | I7: =H7/920 -> 0 | J7: =MIN(Data!D2:D921) -> 1 | K7: =MAX(Data!D2:D921) -> 4 | L7: —
A8: trestbps | B8: Resting BP | C8: Resting blood pressure on admission to hospital | D8: Continuous | E8: mm Hg | F8: — | G8: =COUNTA(Data!E2:E921) -> 861 | H8: =COUNTBLANK(Data!E2:E921) -> 59 | I8: =H8/920 -> 0.064130435 | J8: =MIN(Data!E2:E921) -> 0 | K8: =MAX(Data!E2:E921) -> 200 | L8: =AVERAGE(Data!E2:E921) -> 132.1324
A9: chol | B9: Serum Cholesterol | C9: Serum cholesterol | D9: Continuous | E9: mg/dL | F9: — | G9: =COUNTA(Data!F2:F921) -> 890 | H9: =COUNTBLANK(Data!F2:F921) -> 30 | I9: =H9/920 -> 0.032608696 | J9: =MIN(Data!F2:F921) -> 0 | K9: =MAX(Data!F2:F921) -> 603 | L9: =AVERAGE(Data!F2:F921) -> 199.13034
A10: fbs | B10: Fasting Blood Sugar >120 | C10: Fasting blood sugar > 120 mg/dL | D10: Binary | E10: — | F10: 0 = No; 1 = Yes | G10: =COUNTA(Data!G2:G921) -> 830 | H10: =COUNTBLANK(Data!G2:G921) -> 90 | I10: =H10/920 -> 0.097826087 | J10: =MIN(Data!G2:G921) -> 0 | K10: =MAX(Data!G2:G921) -> 1 | L10: =AVERAGE(Data!G2:G921) -> 0.16626506
A11: restecg | B11: Resting ECG | C11: Resting electrocardiographic results | D11: Categorical | E11: — | F11: 0 = Normal; 1 = ST-T wave abnormality; 2 = Left ventricular hypertrophy | G11: =COUNTA(Data!H2:H921) -> 918 | H11: =COUNTBLANK(Data!H2:H921) -> 2 | I11: =H11/920 -> 0.002173913 | J11: =MIN(Data!H2:H921) -> 0 | K11: =MAX(Data!H2:H921) -> 2 | L11: —
A12: thalach | B12: Max Heart Rate | C12: Maximum heart rate achieved during exercise test | D12: Continuous | E12: bpm | F12: — | G12: =COUNTA(Data!I2:I921) -> 865 | H12: =COUNTBLANK(Data!I2:I921) -> 55 | I12: =H12/920 -> 0.059782609 | J12: =MIN(Data!I2:I921) -> 60 | K12: =MAX(Data!I2:I921) -> 202 | L12: =AVERAGE(Data!I2:I921) -> 137.54566
A13: exang | B13: Exercise-Induced Angina | C13: Exercise-induced angina | D13: Binary | E13: — | F13: 0 = No; 1 = Yes | G13: =COUNTA(Data!J2:J921) -> 865 | H13: =COUNTBLANK(Data!J2:J921) -> 55 | I13: =H13/920 -> 0.059782609 | J13: =MIN(Data!J2:J921) -> 0 | K13: =MAX(Data!J2:J921) -> 1 | L13: =AVERAGE(Data!J2:J921) -> 0.38959538
A14: oldpeak | B14: ST Depression | C14: ST depression induced by exercise relative to rest | D14: Continuous | E14: mm | F14: — | G14: =COUNTA(Data!K2:K921) -> 858 | H14: =COUNTBLANK(Data!K2:K921) -> 62 | I14: =H14/920 -> 0.067391304 | J14: =MIN(Data!K2:K921) -> -2.6 | K14: =MAX(Data!K2:K921) -> 6.2 | L14: =AVERAGE(Data!K2:K921) -> 0.87878788
A15: slope | B15: ST Slope | C15: Slope of the peak exercise ST segment | D15: Categorical | E15: — | F15: 1 = Upsloping; 2 = Flat; 3 = Downsloping | G15: =COUNTA(Data!L2:L921) -> 611 | H15: =COUNTBLANK(Data!L2:L921) -> 309 | I15: =H15/920 -> 0.33586957 | J15: =MIN(Data!L2:L921) -> 1 | K15: =MAX(Data!L2:L921) -> 3 | L15: —
A16: ca | B16: Major Vessels (Fluoroscopy) | C16: Number of major vessels (0–3) colored by fluoroscopy | D16: Ordinal | E16: count | F16: 0 = 0; 1 = 1; 2 = 2; 3 = 3 | G16: =COUNTA(Data!M2:M921) -> 310 | H16: =COUNTBLANK(Data!M2:M921) -> 610 | I16: =H16/920 -> 0.66304348 | J16: =MIN(Data!M2:M921) -> 0 | K16: =MAX(Data!M2:M921) -> 9 | L16: =AVERAGE(Data!M2:M921) -> 0.70322581
A17: thal | B17: Thallium Stress Test | C17: Thallium stress test result | D17: Categorical | E17: — | F17: 3 = Normal; 6 = Fixed defect; 7 = Reversible defect | G17: =COUNTA(Data!N2:N921) -> 434 | H17: =COUNTBLANK(Data!N2:N921) -> 486 | I17: =H17/920 -> 0.52826087 | J17: =MIN(Data!N2:N921) -> 3 | K17: =MAX(Data!N2:N921) -> 7 | L17: —
A18: target | B18: Diagnosis (num) | C18: Angiographic disease status: 0 = <50% diameter narrowing (no disease); 1–4 = >50% narrowing (disease present, increasing severity) | D18: Ordinal | E18: — | F18: 0 = No disease; 1 = Disease (1); 2 = Disease (2); 3 = Disease (3); 4 = Disease (4) | G18: =COUNTA(Data!O2:O921) -> 920 | H18: =COUNTBLANK(Data!O2:O921) -> 0 | I18: =H18/920 -> 0 | J18: =MIN(Data!O2:O921) -> 0 | K18: =MAX(Data!O2:O921) -> 4 | L18: =AVERAGE(Data!O2:O921) -> 1.1336957
A19: site | B19: Data Source Site | C19: Institution that contributed the record | D19: Categorical | E19: — | F19: cleveland = Cleveland Clinic; hungarian = Hungarian Inst. of Cardiology, Budapest; switzerland = University Hospitals, Zurich & Basel; va = VA Medical Center, Long Beach | G19: =COUNTA(Data!P2:P921) -> 920 | H19: =COUNTBLANK(Data!P2:P921) -> 0 | I19: =H19/920 -> 0 | J19: — | K19: — | L19: —
A21: Data Quality Flags
B22: Shaded cells on the Data sheet are flagged below. Values were NOT altered — they appear exactly as in the source.
A23: Field | B23: Count | C23: Issue
A24: chol | B24: 172 | C24: Cholesterol recorded as 0 — physiologically impossible; a placeholder for "not measured" in the source data (all Switzerland records, plus some VA).
A25: trestbps | B25: 1 | C25: Resting BP recorded as 0 — physiologically impossible; likely a missing-value placeholder.
A26: ca | B26: 1 | C26: Value outside the documented 0–3 range; likely a data-entry error / missing code.
A27: oldpeak | B27: 12 | C27: Negative ST depression (i.e., ST elevation). Present in the source; kept as-is.
A28: Record ID | B28: 4 | C28: 2 pairs of exact duplicate records (IDs 394, 467, 860, 908).
A30: Note: the source "target" column is the original UCI "num" field (0–4). For binary use, 0 = no disease and 1–4 = disease present.

Sheet Data
A1: Record ID | B1: Age (age) [years] | C1: Sex (sex) | D1: Chest Pain Type (cp) | E1: Resting BP (trestbps) [mm Hg] | F1: Serum Cholesterol (chol) [mg/dL] | G1: Fasting Blood Sugar >120 (fbs) | H1: Resting ECG (restecg) | I1: Max Heart Rate (thalach) [bpm] | J1: Exercise-Induced Angina (exang) | K1: ST Depression (oldpeak) [mm] | L1: ST Slope (slope) | M1: Major Vessels (Fluoroscopy) (ca) [count] | N1: Thallium Stress Test (thal) | O1: Diagnosis (num) (target) | P1: Data Source Site (site)
A2: 1 | B2: 63 | C2: 1 | D2: 1 | E2: 145 | F2: 233 | G2: 1 | H2: 2 | I2: 150 | J2: 0 | K2: 2.3 | L2: 3 | M2: 0 | N2: 6 | O2: 0 | P2: cleveland
A3: 2 | B3: 67 | C3: 1 | D3: 4 | E3: 160 | F3: 286 | G3: 0 | H3: 2 | I3: 108 | J3: 1 | K3: 1.5 | L3: 2 | M3: 3 | N3: 3 | O3: 2 | P3: cleveland
A4: 3 | B4: 67 | C4: 1 | D4: 4 | E4: 120 | F4: 229 | G4: 0 | H4: 2 | I4: 129 | J4: 1 | K4: 2.6 | L4: 2 | M4: 2 | N4: 7 | O4: 1 | P4: cleveland
A5: 4 | B5: 37 | C5: 1 | D5: 3 | E5: 130 | F5: 250 | G5: 0 | H5: 0 | I5: 187 | J5: 0 | K5: 3.5 | L5: 3 | M5: 0 | N5: 3 | O5: 0 | P5: cleveland
A6: 5 | B6: 41 | C6: 0 | D6: 2 | E6: 130 | F6: 204 | G6: 0 | H6: 2 | I6: 172 | J6: 0 | K6: 1.4 | L6: 1 | M6: 0 | N6: 3 | O6: 0 | P6: cleveland
A7: 6 | B7: 56 | C7: 1 | D7: 2 | E7: 120 | F7: 236 | G7: 0 | H7: 0 | I7: 178 | J7: 0 | K7: 0.8 | L7: 1 | M7: 0 | N7: 3 | O7: 0 | P7: cleveland
A8: 7 | B8: 62 | C8: 0 | D8: 4 | E8: 140 | F8: 268 | G8: 0 | H8: 2 | I8: 160 | J8: 0 | K8: 3.6 | L8: 3 | M8: 2 | N8: 3 | O8: 3 | P8: cleveland
A9: 8 | B9: 57 | C9: 0 | D9: 4 | E9: 120 | F9: 354 | G9: 0 | H9: 0 | I9: 163 | J9: 1 | K9: 0.6 | L9: 1 | M9: 0 | N9: 3 | O9: 0 | P9: cleveland
A10: 9 | B10: 63 | C10: 1 | D10: 4 | E10: 130 | F10: 254 | G10: 0 | H10: 2 | I10: 147 | J10: 0 | K10: 1.4 | L10: 2 | M10: 1 | N10: 7 | O10: 2 | P10: cleveland
A11: 10 | B11: 53 | C11: 1 | D11: 4 | E11: 140 | F11: 203 | G11: 1 | H11: 2 | I11: 155 | J11: 1 | K11: 3.1 | L11: 3 | M11: 0 | N11: 7 | O11: 1 | P11: cleveland
A12: 11 | B12: 57 | C12: 1 | D12: 4 | E12: 140 | F12: 192 | G12: 0 | H12: 0 | I12: 148 | J12: 0 | K12: 0.4 | L12: 2 | M12: 0 | N12: 6 | O12: 0 | P12: cleveland
A13: 12 | B13: 56 | C13: 0 | D13: 2 | E13: 140 | F13: 294 | G13: 0 | H13: 2 | I13: 153 | J13: 0 | K13: 1.3 | L13: 2 | M13: 0 | N13: 3 | O13: 0 | P13: cleveland
... A88: 87 | B88: 47 | C88: 1 | D88: 3 | E88: 138 | F88: 257 | G88: 0 | H88: 2 | I88: 156 | J88: 0 | K88: 0 | L88: 1 | M88: 0 | N88: 3 | O88: 0 | P88: cleveland
A89: 88 | B89: 53 | C89: 0 | D89: 3 | E89: 128 | F89: 216 | G89: 0 | H89: 2 | I89: 115 | J89: 0 | K89: 0 | L89: 1 | M89: 0 | O89: 0 | P89: cleveland
A90: 89 | B90: 53 | C90: 0 | D90: 4 | E90: 138 | F90: 234 | G90: 0 | H90: 2 | I90: 160 | J90: 0 | K90: 0 | L90: 1 | M90: 0 | N90: 3 | O90: 0 | P90: cleveland
A91: 90 | B91: 51 | C91: 0 | D91: 3 | E91: 130 | F91: 256 | G91: 0 | H91: 2 | I91: 149 | J91: 0 | K91: 0.5 | L91: 1 | M91: 0 | N91: 3 | O91: 0 | P91: cleveland
A92: 91 | B92: 66 | C92: 1 | D92: 4 | E92: 120 | F92: 302 | G92: 0 | H92: 2 | I92: 151 | J92: 0 | K92: 0.4 | L92: 2 | M92: 0 | N92: 3 | O92: 0 | P92: cleveland
A93: 92 | B93: 62 | C93: 0 | D93: 4 | E93: 160 | F93: 164 | G93: 0 | H93: 2 | I93: 145 | J93: 0 | K93: 6.2 | L93: 3 | M93: 3 | N93: 7 | O93: 3 | P93: cleveland
A94: 93 | B94: 62 | C94: 1 | D94: 3 | E94: 130 | F94: 231 | G94: 0 | H94: 0 | I94: 146 | J94: 0 | K94: 1.8 | L94: 2 | M94: 3 | N94: 7 | O94: 0 | P94: cleveland
A95: 94 | B95: 44 | C95: 0 | D95: 3 | E95: 108 | F95: 141 | G95: 0 | H95: 0 | I95: 175 | J95: 0 | K95: 0.6 | L95: 2 | M95: 0 | N95: 3 | O95: 0 | P95: cleveland
A96: 95 | B96: 63 | C96: 0 | D96: 3 | E96: 135 | F96: 252 | G96: 0 | H96: 2 | I96: 172 | J96: 0 | K96: 0 | L96: 1 | M96: 0 | N96: 3 | O96: 0 | P96: cleveland
A97: 96 | B97: 52 | C97: 1 | D97: 4 | E97: 128 | F97: 255 | G97: 0 | H97: 0 | I97: 161 | J97: 1 | K97: 0 | L97: 1 | M97: 1 | N97: 7 | O97: 1 | P97: cleveland
A98: 97 | B98: 59 | C98: 1 | D98: 4 | E98: 110 | F98: 239 | G98: 0 | H98: 2 | I98: 142 | J98: 1 | K98: 1.2 | L98: 2 | M98: 1 | N98: 7 | O98: 2 | P98: cleveland
A99: 98 | B99: 60 | C99: 0 | D99: 4 | E99: 150 | F99: 258 | G99: 0 | H99: 2 | I99: 157 | J99: 0 | K99: 2.6 | L99: 2 | M99: 2 | N99: 7 | O99: 3 | P99: cleveland
A100: 99 | B100: 52 | C100: 1 | D100: 2 | E100: 134 | F100: 201 | G100: 0 | H100: 0 | I100: 158 | J100: 0 | K100: 0.8 | L100: 1 | M100: 1 | N100: 3 | O100: 0 | P100: cleveland
A101: 100 | B101: 48 | C101: 1 | D101: 4 | E101: 122 | F101: 222 | G101: 0 | H101: 2 | I101: 186 | J101: 0 | K101: 0 | L101: 1 | M101: 0 | N101: 3 | O101: 0 | P101: cleveland
... A167: 166 | B167: 57 | C167: 1 | D167: 4 | E167: 132 | F167: 207 | G167: 0 | H167: 0 | I167: 168 | J167: 1 | K167: 0 | L167: 1 | M167: 0 | N167: 7 | O167: 0 | P167: cleveland
A168: 167 | B168: 52 | C168: 1 | D168: 3 | E168: 138 | F168: 223 | G168: 0 | H168: 0 | I168: 169 | J168: 0 | K168: 0 | L168: 1 | N168: 3 | O168: 0 | P168: cleveland
A169: 168 | B169: 54 | C169: 0 | D169: 2 | E169: 132 | F169: 288 | G169: 1 | H169: 2 | I169: 159 | J169: 1 | K169: 0 | L169: 1 | M169: 1 | N169: 3 | O169: 0 | P169: cleveland
A170: 169 | B170: 35 | C170: 1 | D170: 4 | E170: 126 | F170: 282 | G170: 0 | H170: 2 | I170: 156 | J170: 1 | K170: 0 | L170: 1 | M170: 0 | N170: 7 | O170: 1 | P170: cleveland
A171: 170 | B171: 45 | C171: 0 | D171: 2 | E171: 112 | F171: 160 | G171: 0 | H171: 0 | I171: 138 | J171: 0 | K171: 0 | L171: 2 | M171: 0 | N171: 3 | O171: 0 | P171: cleveland
A172: 171 | B172: 70 | C172: 1 | D172: 3 | E172: 160 | F172: 269 | G172: 0 | H172: 0 | I172: 112 | J172: 1 | K172: 2.9 | L172: 2 | M172: 1 | N172: 7 | O172: 3 | P172: cleveland
A173: 172 | B173: 53 | C173: 1 | D173: 4 | E173: 142 | F173: 226 | G173: 0 | H173: 2 | I173: 111 | J173: 1 | K173: 0 | L173: 1 | M173: 0 | N173: 7 | O173: 0 | P173: cleveland
A174: 173 | B174: 59 | C174: 0 | D174: 4 | E174: 174 | F174: 249 | G174: 0 | H174: 0 | I174: 143 | J174: 1 | K174: 0 | L174: 2 | M174: 0 | N174: 3 | O174: 1 | P174: cleveland
A175: 174 | B175: 62 | C175: 0 | D175: 4 | E175: 140 | F175: 394 | G175: 0 | H175: 2 | I175: 157 | J175: 0 | K175: 1.2 | L175: 2 | M175: 0 | N175: 3 | O175: 0 | P175: cleveland
A176: 175 | B176: 64 | C176: 1 | D176: 4 | E176: 145 | F176: 212 | G176: 0 | H176: 2 | I176: 132 | J176: 0 | K176: 2 | L176: 2 | M176: 2 | N176: 6 | O176: 4 | P176: cleveland
A177: 176 | B177: 57 | C177: 1 | D177: 4 | E177: 152 | F177: 274 | G177: 0 | H177: 0 | I177: 88 | J177: 1 | K177: 1.2 | L177: 2 | M177: 1 | N177: 7 | O177: 1 | P177: cleveland
A178: 177 | B178: 52 | C178: 1 | D178: 4 | E178: 108 | F178: 233 | G178: 1 | H178: 0 | I178: 147 | J178: 0 | K178: 0.1 | L178: 1 | M178: 3 | N178: 7 | O178: 0 | P178: cleveland
A179: 178 | B179: 56 | C179: 1 | D179: 4 | E179: 132 | F179: 184 | G179: 0 | H179: 2 | I179: 105 | J179: 1 | K179: 2.1 | L179: 2 | M179: 1 | N179: 6 | O179: 1 | P179: cleveland
...

Sheet Codes
A1: Code Lookup Tables
A2: Category labels used by the "Data (Labeled)" sheet. Edit a label here and it updates everywhere.
A4: Sex (sex)
A5: Code | B5: Label
A6: 0 | B6: Female
A7: 1 | B7: Male
A9: Chest Pain Type (cp)
A10: Code | B10: Label
A11: 1 | B11: Typical angina
A12: 2 | B12: Atypical angina
A13: 3 | B13: Non-anginal pain
A14: 4 | B14: Asymptomatic
A16: Fasting Blood Sugar >120 (fbs)
A17: Code | B17: Label
A18: 0 | B18: No
A19: 1 | B19: Yes
A21: Resting ECG (restecg)
A22: Code | B22: Label
A23: 0 | B23: Normal
A24: 1 | B24: ST-T wave abnormality
A25: 2 | B25: Left ventricular hypertrophy
A27: Exercise-Induced Angina (exang)
A28: Code | B28: Label
A29: 0 | B29: No
A30: 1 | B30: Yes
A32: ST Slope (slope)
A33: Code | B33: Label
A34: 1 | B34: Upsloping
A35: 2 | B35: Flat
A36: 3 | B36: Downsloping
A38: Major Vessels (Fluoroscopy) (ca)
A39: Code | B39: Label
A40: 0 | B40: 0
A41: 1 | B41: 1
A42: 2 | B42: 2
A43: 3 | B43: 3
A45: Thallium Stress Test (thal)
A46: Code | B46: Label
A47: 3 | B47: Normal
A48: 6 | B48: Fixed defect
...

Sheet Data (Labeled)
A1: Record ID | B1: Age [years] | C1: Sex | D1: Chest Pain Type | E1: Resting BP [mm Hg] | F1: Serum Cholesterol [mg/dL] | G1: Fasting Blood Sugar >120 | H1: Resting ECG | I1: Max Heart Rate [bpm] | J1: Exercise-Induced Angina | K1: ST Depression [mm] | L1: ST Slope | M1: Major Vessels (Fluoroscopy) [count] | N1: Thallium Stress Test | O1: Diagnosis (num) | P1: Data Source Site
A2: =Data!A2 -> 1 | B2: =IF(Data!B2="","",Data!B2) -> 63 | C2: =IF(Data!C2="","",IFERROR(VLOOKUP(Data!C2,Codes!$A$6:$B$7,2,FALSE()),"Invalid ("&Data!C2&")")) -> Male | D2: =IF(Data!D2="","",IFERROR(VLOOKUP(Data!D2,Codes!$A$11:$B$14,2,FALSE()),"Invalid ("&Data!D2&")")) -> Typical angina | E2: =IF(Data!E2="","",Data!E2) -> 145 | F2: =IF(Data!F2="","",Data!F2) -> 233 | G2: =IF(Data!G2="","",IFERROR(VLOOKUP(Data!G2,Codes!$A$18:$B$19,2,FALSE()),"Invalid ("&Data!G2&")")) -> Yes | H2: =IF(Data!H2="","",IFERROR(VLOOKUP(Data!H2,Codes!$A$23:$B$25,2,FALSE()),"Invalid ("&Data!H2&")")) -> Left ventricular hypertrophy | I2: =IF(Data!I2="","",Data!I2) -> 150 | J2: =IF(Data!J2="","",IFERROR(VLOOKUP(Data!J2,Codes!$A$29:$B$30,2,FALSE()),"Invalid ("&Data!J2&")")) -> No | K2: =IF(Data!K2="","",Data!K2) -> 2.3 | L2: =IF(Data!L2="","",IFERROR(VLOOKUP(Data!L2,Codes!$A$34:$B$36,2,FALSE()),"Invalid ("&Data!L2&")")) -> Downsloping | M2: =IF(Data!M2="","",Data!M2) -> 0 | N2: =IF(Data!N2="","",IFERROR(VLOOKUP(Data!N2,Codes!$A$47:$B$49,2,FALSE()),"Invalid ("&Data!N2&")")) -> Fixed defect | O2: =IF(Data!O2="","",IFERROR(VLOOKUP(Data!O2,Codes!$A$53:$B$57,2,FALSE()),"Invalid ("&Data!O2&")")) -> No disease | P2: =IF(Data!P2="","",IFERROR(VLOOKUP(Data!P2,Codes!$A$61:$B$64,2,FALSE()),"Invalid ("&Data!P2&")")) -> Cleveland Clinic
A3: =Data!A3 -> 2 | B3: =IF(Data!B3="","",Data!B3) -> 67 | C3: =IF(Data!C3="","",IFERROR(VLOOKUP(Data!C3,Codes!$A$6:$B$7,2,FALSE()),"Invalid ("&Data!C3&")")) -> Male | D3: =IF(Data!D3="","",IFERROR(VLOOKUP(Data!D3,Codes!$A$11:$B$14,2,FALSE()),"Invalid ("&Data!D3&")")) -> Asymptomatic | E3: =IF(Data!E3="","",Data!E3) -> 160 | F3: =IF(Data!F3="","",Data!F3) -> 286 | G3: =IF(Data!G3="","",IFERROR(VLOOKUP(Data!G3,Codes!$A$18:$B$19,2,FALSE()),"Invalid ("&Data!G3&")")) -> No | H3: =IF(Data!H3="","",IFERROR(VLOOKUP(Data!H3,Codes!$A$23:$B$25,2,FALSE()),"Invalid ("&Data!H3&")")) -> Left ventricular hypertrophy | I3: =IF(Data!I3="","",Data!I3) -> 108 | J3: =IF(Data!J3="","",IFERROR(VLOOKUP(Data!J3,Codes!$A$29:$B$30,2,FALSE()),"Invalid ("&Data!J3&")")) -> Yes | K3: =IF(Data!K3="","",Data!K3) -> 1.5 | L3: =IF(Data!L3="","",IFERROR(VLOOKUP(Data!L3,Codes!$A$34:$B$36,2,FALSE()),"Invalid ("&Data!L3&")")) -> Flat | M3: =IF(Data!M3="","",Data!M3) -> 3 | N3: =IF(Data!N3="","",IFERROR(VLOOKUP(Data!N3,Codes!$A$47:$B$49,2,FALSE()),"Invalid ("&Data!N3&")")) -> Normal | O3: =IF(Data!O3="","",IFERROR(VLOOKUP(Data!O3,Codes!$A$53:$B$57,2,FALSE()),"Invalid ("&Data!O3&")")) -> Disease (2) | P3: =IF(Data!P3="","",IFERROR(VLOOKUP(Data!P3,Codes!$A$61:$B$64,2,FALSE()),"Invalid ("&Data!P3&")")) -> Cleveland Clinic
A4: =Data!A4 -> 3 | B4: =IF(Data!B4="","",Data!B4) -> 67 | C4: =IF(Data!C4="","",IFERROR(VLOOKUP(Data!C4,Codes!$A$6:$B$7,2,FALSE()),"Invalid ("&Data!C4&")")) -> Male | D4: =IF(Data!D4="","",IFERROR(VLOOKUP(Data!D4,Codes!$A$11:$B$14,2,FALSE()),"Invalid ("&Data!D4&")")) -> Asymptomatic | E4: =IF(Data!E4="","",Data!E4) -> 120 | F4: =IF(Data!F4="","",Data!F4) -> 229 | G4: =IF(Data!G4="","",IFERROR(VLOOKUP(Data!G4,Codes!$A$18:$B$19,2,FALSE()),"Invalid ("&Data!G4&")")) -> No | H4: =IF(Data!H4="","",IFERROR(VLOOKUP(Data!H4,Codes!$A$23:$B$25,2,FALSE()),"Invalid ("&Data!H4&")")) -> Left ventricular hypertrophy | I4: =IF(Data!I4="","",Data!I4) -> 129 | J4: =IF(Data!J4="","",IFERROR(VLOOKUP(Data!J4,Codes!$A$29:$B$30,2,FALSE()),"Invalid ("&Data!J4&")")) -> Yes | K4: =IF(Data!K4="","",Data!K4) -> 2.6 | L4: =IF(Data!L4="","",IFERROR(VLOOKUP(Data!L4,Codes!$A$34:$B$36,2,FALSE()),"Invalid ("&Data!L4&")")) -> Flat | M4: =IF(Data!M4="","",Data!M4) -> 2 | N4: =IF(Data!N4="","",IFERROR(VLOOKUP(Data!N4,Codes!$A$47:$B$49,2,FALSE()),"Invalid ("&Data!N4&")")) -> Reversible defect | O4: =IF(Data!O4="","",IFERROR(VLOOKUP(Data!O4,Codes!$A$53:$B$57,2,FALSE()),"Invalid ("&Data!O4&")")) -> Disease (1) | P4: =IF(Data!P4="","",IFERROR(VLOOKUP(Data!P4,Codes!$A$61:$B$64,2,FALSE()),"Invalid ("&Data!P4&")")) -> Cleveland Clinic
A5: =Data!A5 -> 4 | B5: =IF(Data!B5="","",Data!B5) -> 37 | C5: =IF(Data!C5="","",IFERROR(VLOOKUP(Data!C5,Codes!$A$6:$B$7,2,FALSE()),"Invalid ("&Data!C5&")")) -> Male | D5: =IF(Data!D5="","",IFERROR(VLOOKUP(Data!D5,Codes!$A$11:$B$14,2,FALSE()),"Invalid ("&Data!D5&")")) -> Non-anginal pain | E5: =IF(Data!E5="","",Data!E5) -> 130 | F5: =IF(Data!F5="","",Data!F5) -> 250 | G5: =IF(Data!G5="","",IFERROR(VLOOKUP(Data!G5,Codes!$A$18:$B$19,2,FALSE()),"Invalid ("&Data!G5&")")) -> No | H5: =IF(Data!H5="","",IFERROR(VLOOKUP(Data!H5,Codes!$A$23:$B$25,2,FALSE()),"Invalid ("&Data!H5&")")) -> Normal | I5: =IF(Data!I5="","",Data!I5) -> 187 | J5: =IF(Data!J5="","",IFERROR(VLOOKUP(Data!J5,Codes!$A$29:$B$30,2,FALSE()),"Invalid ("&Data!J5&")")) -> No | K5: =IF(Data!K5="","",Data!K5) -> 3.5 | L5: =IF(Data!L5="","",IFERROR(VLOOKUP(Data!L5,Codes!$A$34:$B$36,2,FALSE()),"Invalid ("&Data!L5&")")) -> Downsloping | M5: =IF(Data!M5="","",Data!M5) -> 0 | N5: =IF(Data!N5="","",IFERROR(VLOOKUP(Data!N5,Codes!$A$47:$B$49,2,FALSE()),"Invalid ("&Data!N5&")")) -> Normal | O5: =IF(Data!O5="","",IFERROR(VLOOKUP(Data!O5,Codes!$A$53:$B$57,2,FALSE()),"Invalid ("&Data!O5&")")) -> No disease | P5: =IF(Data!P5="","",IFERROR(VLOOKUP(Data!P5,Codes!$A$61:$B$64,2,FALSE()),"Invalid ("&Data!P5&")")) -> Cleveland Clinic
A6: =Data!A6 -> 5 | B6: =IF(Data!B6="","",Data!B6) -> 41 | C6: =IF(Data!C6="","",IFERROR(VLOOKUP(Data!C6,Codes!$A$6:$B$7,2,FALSE()),"Invalid ("&Data!C6&")")) -> Female | D6: =IF(Data!D6="","",IFERROR(VLOOKUP(Data!D6,Codes!$A$11:$B$14,2,FALSE()),"Invalid ("&Data!D6&")")) -> Atypical angina | E6: =IF(Data!E6="","",Data!E6) -> 130 | F6: =IF(Data!F6="","",Data!F6) -> 204 | G6: =IF(Data!G6="","",IFERROR(VLOOKUP(Data!G6,Codes!$A$18:$B$19,2,FALSE()),"Invalid ("&Data!G6&")")) -> No | H6: =IF(Data!H6="","",IFERROR(VLOOKUP(Data!H6,Codes!$A$23:$B$25,2,FALSE()),"Invalid ("&Data!H6&")")) -> Left ventricular hypertrophy | I6: =IF(Data!I6="","",Data!I6) -> 172 | J6: =IF(Data!J6="","",IFERROR(VLOOKUP(Data!J6,Codes!$A$29:$B$30,2,FALSE()),"Invalid ("&Data!J6&")")) -> No | K6: =IF(Data!K6="","",Data!K6) -> 1.4 | L6: =IF(Data!L6="","",IFERROR(VLOOKUP(Data!L6,Codes!$A$34:$B$36,2,FALSE()),"Invalid ("&Data!L6&")")) -> Upsloping | M6: =IF(Data!M6="","",Data!M6) -> 0 | N6: =IF(Data!N6="","",IFERROR(VLOOKUP(Data!N6,Codes!$A$47:$B$49,2,FALSE()),"Invalid ("&Data!N6&")")) -> Normal | O6: =IF(Data!O6="","",IFERROR(VLOOKUP(Data!O6,Codes!$A$53:$B$57,2,FALSE()),"Invalid ("&Data!O6&")")) -> No disease | P6: =IF(Data!P6="","",IFERROR(VLOOKUP(Data!P6,Codes!$A$61:$B$64,2,FALSE()),"Invalid ("&Data!P6&")")) -> Cleveland Clinic
A7: =Data!A7 -> 6 | B7: =IF(Data!B7="","",Data!B7) -> 56 | C7: =IF(Data!C7="","",IFERROR(VLOOKUP(Data!C7,Codes!$A$6:$B$7,2,FALSE()),"Invalid ("&Data!C7&")")) -> Male | D7: =IF(Data!D7="","",IFERROR(VLOOKUP(Data!D7,Codes!$A$11:$B$14,2,FALSE()),"Invalid ("&Data!D7&")")) -> Atypical angina | E7: =IF(Data!E7="","",Data!E7) -> 120 | F7: =IF(Data!F7="","",Data!F7) -> 236 | G7: =IF(Data!G7="","",IFERROR(VLOOKUP(Data!G7,Codes!$A$18:$B$19,2,FALSE()),"Invalid ("&Data!G7&")")) -> No | H7: =IF(Data!H7="","",IFERROR(VLOOKUP(Data!H7,Codes!$A$23:$B$25,2,FALSE()),"Invalid ("&Data!H7&")")) -> Normal | I7: =IF(Data!I7="","",Data!I7) -> 178 | J7: =IF(Data!J7="","",IFERROR(VLOOKUP(Data!J7,Codes!$A$29:$B$30,2,FALSE()),"Invalid ("&Data!J7&")")) -> No | K7: =IF(Data!K7="","",Data!K7) -> 0.8 | L7: =IF(Data!L7="","",IFERROR(VLOOKUP(Data!L7,Codes!$A$34:$B$36,2,FALSE()),"Invalid ("&Data!L7&")")) -> Upsloping | M7: =IF(Data!M7="","",Data!M7) -> 0 | N7: =IF(Data!N7="","",IFERROR(VLOOKUP(Data!N7,Codes!$A$47:$B$49,2,FALSE()),"Invalid ("&Data!N7&")")) -> Normal | O7: =IF(Data!O7="","",IFERROR(VLOOKUP(Data!O7,Codes!$A$53:$B$57,2,FALSE()),"Invalid ("&Data!O7&")")) -> No disease | P7: =IF(Data!P7="","",IFERROR(VLOOKUP(Data!P7,Codes!$A$61:$B$64,2,FALSE()),"Invalid ("&Data!P7&")")) -> Cleveland Clinic
A8: =Data!A8 -> 7 | B8: =IF(Data!B8="","",Data!B8) -> 62 | C8: =IF(Data!C8="","",IFERROR(VLOOKUP(Data!C8,Codes!$A$6:$B$7,2,FALSE()),"Invalid ("&Data!C8&")")) -> Female | D8: =IF(Data!D8="","",IFERROR(VLOOKUP(Data!D8,Codes!$A$11:$B$14,2,FALSE()),"Invalid ("&Data!D8&")")) -> Asymptomatic | E8: =IF(Data!E8="","",Data!E8) -> 140 | F8: =IF(Data!F8="","",Data!F8) -> 268 | G8: =IF(Data!G8="","",IFERROR(VLOOKUP(Data!G8,Codes!$A$18:$B$19,2,FALSE()),"Invalid ("&Data!G8&")")) -> No | H8: =IF(Data!H8="","",IFERROR(VLOOKUP(Data!H8,Codes!$A$23:$B$25,2,FALSE()),"Invalid ("&Data!H8&")")) -> Left ventricular hypertrophy | I8: =IF(Data!I8="","",Data!I8) -> 160 | J8: =IF(Data!J8="","",IFERROR(VLOOKUP(Data!J8,Codes!$A$29:$B$30,2,FALSE()),"Invalid ("&Data!J8&")")) -> No | K8: =IF(Data!K8="","",Data!K8) -> 3.6 | L8: =IF(Data!L8="","",IFERROR(VLOOKUP(Data!L8,Codes!$A$34:$B$36,2,FALSE()),"Invalid ("&Data!L8&")")) -> Downsloping | M8: =IF(Data!M8="","",Data!M8) -> 2 | N8: =IF(Data!N8="","",IFERROR(VLOOKUP(Data!N8,Codes!$A$47:$B$49,2,FALSE()),"Invalid ("&Data!N8&")")) -> Normal | O8: =IF(Data!O8="","",IFERROR(VLOOKUP(Data!O8,Codes!$A$53:$B$57,2,FALSE()),"Invalid ("&Data!O8&")")) -> Disease (3) | P8: =IF(Data!P8="","",IFERROR(VLOOKUP(Data!P8,Codes!$A$61:$B$64,2,FALSE()),"Invalid ("&Data!P8&")")) -> Cleveland Clinic
A9: =Data!A9 -> 8 | B9: =IF(Data!B9="","",Data!B9) -> 57 | C9: =IF(Data!C9="","",IFERROR(VLOOKUP(Data!C9,Codes!$A$6:$B$7,2,FALSE()),"Invalid ("&Data!C9&")")) -> Female | D9: =IF(Data!D9="","",IFERROR(VLOOKUP(Data!D9,Codes!$A$11:$B$14,2,FALSE()),"Invalid ("&Data!D9&")")) -> Asymptomatic | E9: =IF(Data!E9="","",Data!E9) -> 120 | F9: =IF(Data!F9="","",Data!F9) -> 354 | G9: =IF(Data!G9="","",IFERROR(VLOOKUP(Data!G9,Codes!$A$18:$B$19,2,FALSE()),"Invalid ("&Data!G9&")")) -> No | H9: =IF(Data!H9="","",IFERROR(VLOOKUP(Data!H9,Codes!$A$23:$B$25,2,FALSE()),"Invalid ("&Data!H9&")")) -> Normal | I9: =IF(Data!I9="","",Data!I9) -> 163 | J9: =IF(Data!J9="","",IFERROR(VLOOKUP(Data!J9,Codes!$A$29:$B$30,2,FALSE()),"Invalid ("&Data!J9&")")) -> Yes | K9: =IF(Data!K9="","",Data!K9) -> 0.6 | L9: =IF(Data!L9="","",IFERROR(VLOOKUP(Data!L9,Codes!$A$34:$B$36,2,FALSE()),"Invalid ("&Data!L9&")")) -> Upsloping | M9: =IF(Data!M9="","",Data!M9) -> 0 | N9: =IF(Data!N9="","",IFERROR(VLOOKUP(Data!N9,Codes!$A$47:$B$49,2,FALSE()),"Invalid ("&Data!N9&")")) -> Normal | O9: =IF(Data!O9="","",IFERROR(VLOOKUP(Data!O9,Codes!$A$53:$B$57,2,FALSE()),"Invalid ("&Data!O9&")")) -> No disease | P9: =IF(Data!P9="","",IFERROR(VLOOKUP(Data!P9,Codes!$A$61:$B$64,2,FALSE()),"Invalid ("&Data!P9&")")) -> Cleveland Clinic
A10: =Data!A10 -> 9 | B10: =IF(Data!B10="","",Data!B10) -> 63 | C10: =IF(Data!C10="","",IFERROR(VLOOKUP(Data!C10,Codes!$A$6:$B$7,2,FALSE()),"Invalid ("&Data!C10&")")) -> Male | D10: =IF(Data!D10="","",IFERROR(VLOOKUP(Data!D10,Codes!$A$11:$B$14,2,FALSE()),"Invalid ("&Data!D10&")")) -> Asymptomatic | E10: =IF(Data!E10="","",Data!E10) -> 130 | F10: =IF(Data!F10="","",Data!F10) -> 254 | G10: =IF(Data!G10="","",IFERROR(VLOOKUP(Data!G10,Codes!$A$18:$B$19,2,FALSE()),"Invalid ("&Data!G10&")")) -> No | H10: =IF(Data!H10="","",IFERROR(VLOOKUP(Data!H10,Codes!$A$23:$B$25,2,FALSE()),"Invalid ("&Data!H10&")")) -> Left ventricular hypertrophy | I10: =IF(Data!I10="","",Data!I10) -> 147 | J10: =IF(Data!J10="","",IFERROR(VLOOKUP(Data!J10,Codes!$A$29:$B$30,2,FALSE()),"Invalid ("&Data!J10&")")) -> No | K10: =IF(Data!K10="","",Data!K10) -> 1.4 | L10: =IF(Data!L10="","",IFERROR(VLOOKUP(Data!L10,Codes!$A$34:$B$36,2,FALSE()),"Invalid ("&Data!L10&")")) -> Flat | M10: =IF(Data!M10="","",Data!M10) -> 1 | N10: =IF(Data!N10="","",IFERROR(VLOOKUP(Data!N10,Codes!$A$47:$B$49,2,FALSE()),"Invalid ("&Data!N10&")")) -> Reversible defect | O10: =IF(Data!O10="","",IFERROR(VLOOKUP(Data!O10,Codes!$A$53:$B$57,2,FALSE()),"Invalid ("&Data!O10&")")) -> Disease (2) | P10: =IF(Data!P10="","",IFERROR(VLOOKUP(Data!P10,Codes!$A$61:$B$64,2,FALSE()),"Invalid ("&Data!P10&")")) -> Cleveland Clinic
A11: =Data!A11 -> 10 | B11: =IF(Data!B11="","",Data!B11) -> 53 | C11: =IF(Data!C11="","",IFERROR(VLOOKUP(Data!C11,Codes!$A$6:$B$7,2,FALSE()),"Invalid ("&Data!C11&")")) -> Male | D11: =IF(Data!D11="","",IFERROR(VLOOKUP(Data!D11,Codes!$A$11:$B$14,2,FALSE()),"Invalid ("&Data!D11&")")) -> Asymptomatic | E11: =IF(Data!E11="","",Data!E11) -> 140 | F11: =IF(Data!F11="","",Data!F11) -> 203 | G11: =IF(Data!G11="","",IFERROR(VLOOKUP(Data!G11,Codes!$A$18:$B$19,2,FALSE()),"Invalid ("&Data!G11&")")) -> Yes | H11: =IF(Data!H11="","",IFERROR(VLOOKUP(Data!H11,Codes!$A$23:$B$25,2,FALSE()),"Invalid ("&Data!H11&")")) -> Left ventricular hypertrophy | I11: =IF(Data!I11="","",Data!I11) -> 155 | J11: =IF(Data!J11="","",IFERROR(VLOOKUP(Data!J11,Codes!$A$29:$B$30,2,FALSE()),"Invalid ("&Data!J11&")")) -> Yes | K11: =IF(Data!K11="","",Data!K11) -> 3.1 | L11: =IF(Data!L11="","",IFERROR(VLOOKUP(Data!L11,Codes!$A$34:$B$36,2,FALSE()),"Invalid ("&Data!L11&")")) -> Downsloping | M11: =IF(Data!M11="","",Data!M11) -> 0 | N11: =IF(Data!N11="","",IFERROR(VLOOKUP(Data!N11,Codes!$A$47:$B$49,2,FALSE()),"Invalid ("&Data!N11&")")) -> Reversible defect | O11: =IF(Data!O11="","",IFERROR(VLOOKUP(Data!O11,Codes!$A$53:$B$57,2,FALSE()),"Invalid ("&Data!O11&")")) -> Disease (1) | P11: =IF(Data!P11="","",IFERROR(VLOOKUP(Data!P11,Codes!$A$61:$B$64,2,FALSE()),"Invalid ("&Data!P11&")")) -> Cleveland Clinic
A12: =Data!A12 -> 11 | B12: =IF(Data!B12="","",Data!B12) -> 57 | C12: =IF(Data!C12="","",IFERROR(VLOOKUP(Data!C12,Codes!$A$6:$B$7,2,FALSE()),"Invalid ("&Data!C12&")")) -> Male | D12: =IF(Data!D12="","",IFERROR(VLOOKUP(Data!D12,Codes!$A$11:$B$14,2,FALSE()),"Invalid ("&Data!D12&")")) -> Asymptomatic | E12: =IF(Data!E12="","",Data!E12) -> 140 | F12: =IF(Data!F12="","",Data!F12) -> 192 | G12: =IF(Data!G12="","",IFERROR(VLOOKUP(Data!G12,Codes!$A$18:$B$19,2,FALSE()),"Invalid ("&Data!G12&")")) -> No | H12: =IF(Data!H12="","",IFERROR(VLOOKUP(Data!H12,Codes!$A$23:$B$25,2,FALSE()),"Invalid ("&Data!H12&")")) -> Normal | I12: =IF(Data!I12="","",Data!I12) -> 148 | J12: =IF(Data!J12="","",IFERROR(VLOOKUP(Data!J12,Codes!$A$29:$B$30,2,FALSE()),"Invalid ("&Data!J12&")")) -> No | K12: =IF(Data!K12="","",Data!K12) -> 0.4 | L12: =IF(Data!L12="","",IFERROR(VLOOKUP(Data!L12,Codes!$A$34:$B$36,2,FALSE()),"Invalid ("&Data!L12&")")) -> Flat | M12: =IF(Data!M12="","",Data!M12) -> 0 | N12: =IF(Data!N12="","",IFERROR(VLOOKUP(Data!N12,Codes!$A$47:$B$49,2,FALSE()),"Invalid ("&Data!N12&")")) -> Fixed defect | O12: =IF(Data!O12="","",IFERROR(VLOOKUP(Data!O12,Codes!$A$53:$B$57,2,FALSE()),"Invalid ("&Data!O12&")")) -> No disease | P12: =IF(Data!P12="","",IFERROR(VLOOKUP(Data!P12,Codes!$A$61:$B$64,2,FALSE()),"Invalid ("&Data!P12&")")) -> Cleveland Clinic
A13: =Data!A13 -> 12 | B13: =IF(Data!B13="","",Data!B13) -> 56 | C13: =IF(Data!C13="","",IFERROR(VLOOKUP(Data!C13,Codes!$A$6:$B$7,2,FALSE()),"Invalid ("&Data!C13&")")) -> Female | D13: =IF(Data!D13="","",IFERROR(VLOOKUP(Data!D13,Codes!$A$11:$B$14,2,FALSE()),"Invalid ("&Data!D13&")")) -> Atypical angina | E13: =IF(Data!E13="","",Data!E13) -> 140 | F13: =IF(Data!F13="","",Data!F13) -> 294 | G13: =IF(Data!G13="","",IFERROR(VLOOKUP(Data!G13,Codes!$A$18:$B$19,2,FALSE()),"Invalid ("&Data!G13&")")) -> No | H13: =IF(Data!H13="","",IFERROR(VLOOKUP(Data!H13,Codes!$A$23:$B$25,2,FALSE()),"Invalid ("&Data!H13&")")) -> Left ventricular hypertrophy | I13: =IF(Data!I13="","",Data!I13) -> 153 | J13: =IF(Data!J13="","",IFERROR(VLOOKUP(Data!J13,Codes!$A$29:$B$30,2,FALSE()),"Invalid ("&Data!J13&")")) -> No | K13: =IF(Data!K13="","",Data!K13) -> 1.3 | L13: =IF(Data!L13="","",IFERROR(VLOOKUP(Data!L13,Codes!$A$34:$B$36,2,FALSE()),"Invalid ("&Data!L13&")")) -> Flat | M13: =IF(Data!M13="","",Data!M13) -> 0 | N13: =IF(Data!N13="","",IFERROR(VLOOKUP(Data!N13,Codes!$A$47:$B$49,2,FALSE()),"Invalid ("&Data!N13&")")) -> Normal | O13: =IF(Data!O13="","",IFERROR(VLOOKUP(Data!O13,Codes!$A$53:$B$57,2,FALSE()),"Invalid ("&Data!O13&")")) -> No disease | P13: =IF(Data!P13="","",IFERROR(VLOOKUP(Data!P13,Codes!$A$61:$B$64,2,FALSE()),"Invalid ("&Data!P13&")")) -> Cleveland Clinic
... A921: =Data!A921 -> 920 | B921: =IF(Data!B921="","",Data!B921) -> 62 | C921: =IF(Data!C921="","",IFERROR(VLOOKUP(Data!C921,Codes!$A$6:$B$7,2,FALSE()),"Invalid ("&Data!C921&")")) -> Male | D921: =IF(Data!D921="","",IFERROR(VLOOKUP(Data!D921,Codes!$A$11:$B$14,2,FALSE()),"Invalid ("&Data!D921&")")) -> Atypical angina | E921: =IF(Data!E921="","",Data!E921) -> 120 | F921: =IF(Data!F921="","",Data!F921) -> 254 | G921: =IF(Data!G921="","",IFERROR(VLOOKUP(Data!G921,Codes!$A$18:$B$19,2,FALSE()),"Invalid ("&Data!G921&")")) -> No | H921: =IF(Data!H921="","",IFERROR(VLOOKUP(Data!H921,Codes!$A$23:$B$25,2,FALSE()),"Invalid ("&Data!H921&")")) -> Left ventricular hypertrophy | I921: =IF(Data!I921="","",Data!I921) -> 93 | J921: =IF(Data!J921="","",IFERROR(VLOOKUP(Data!J921,Codes!$A$29:$B$30,2,FALSE()),"Invalid ("&Data!J921&")")) -> Yes | K921: =IF(Data!K921="","",Data!K921) -> 0 | L921: =IF(Data!L921="","",IFERROR(VLOOKUP(Data!L921,Codes!$A$34:$B$36,2,FALSE()),"Invalid ("&Data!L921&")")) | M921: =IF(Data!M921="","",Data!M921) | N921: =IF(Data!N921="","",IFERROR(VLOOKUP(Data!N921,Codes!$A$47:$B$49,2,FALSE()),"Invalid ("&Data!N921&")")) | O921: =IF(Data!O921="","",IFERROR(VLOOKUP(Data!O921,Codes!$A$53:$B$57,2,FALSE()),"Invalid ("&Data!O921&")")) -> Disease (1) | P921: =IF(Data!P921="","",IFERROR(VLOOKUP(Data!P921,Codes!$A$61:$B$64,2,FALSE()),"Invalid ("&Data!P921&")")) -> VA Medical Center, Long Beach

Sheet Summary by Site
A1: Summary by Site
A3: Metric | B3: Cleveland Clinic | C3: Hungarian Inst. of Cardiology, Budapest | D3: University Hospitals, Zurich & Basel | E3: VA Medical Center, Long Beach | F3: All Sites
A4: Records | B4: =COUNTIF(Data!$P$2:$P$921,"cleveland") -> 303 | C4: =COUNTIF(Data!$P$2:$P$921,"hungarian") -> 294 | D4: =COUNTIF(Data!$P$2:$P$921,"switzerland") -> 123 | E4: =COUNTIF(Data!$P$2:$P$921,"va") -> 200 | F4: =COUNTA(Data!$P$2:$P$921) -> 920
A5: Male | B5: =COUNTIFS(Data!$P$2:$P$921,"cleveland",Data!$C$2:$C$921,1)/B$4 -> 0.67986799 | C5: =COUNTIFS(Data!$P$2:$P$921,"hungarian",Data!$C$2:$C$921,1)/C$4 -> 0.7244898 | D5: =COUNTIFS(Data!$P$2:$P$921,"switzerland",Data!$C$2:$C$921,1)/D$4 -> 0.91869919 | E5: =COUNTIFS(Data!$P$2:$P$921,"va",Data!$C$2:$C$921,1)/E$4 -> 0.97 | F5: =COUNTIF(Data!$C$2:$C$921,1)/F$4 -> 0.78913043
A6: Disease present (target 1–4) | B6: =COUNTIFS(Data!$P$2:$P$921,"cleveland",Data!$O$2:$O$921,">0")/B$4 -> 0.45874587 | C6: =COUNTIFS(Data!$P$2:$P$921,"hungarian",Data!$O$2:$O$921,">0")/C$4 -> 0.36054422 | D6: =COUNTIFS(Data!$P$2:$P$921,"switzerland",Data!$O$2:$O$921,">0")/D$4 -> 0.93495935 | E6: =COUNTIFS(Data!$P$2:$P$921,"va",Data!$O$2:$O$921,">0")/E$4 -> 0.745 | F6: =COUNTIF(Data!$O$2:$O$921,">0")/F$4 -> 0.55326087
A7: Mean Age [years] | B7: =AVERAGEIFS(Data!$B$2:$B$921,Data!$P$2:$P$921,"cleveland") -> 54.438944 | C7: =AVERAGEIFS(Data!$B$2:$B$921,Data!$P$2:$P$921,"hungarian") -> 47.826531 | D7: =AVERAGEIFS(Data!$B$2:$B$921,Data!$P$2:$P$921,"switzerland") -> 55.317073 | E7: =AVERAGEIFS(Data!$B$2:$B$921,Data!$P$2:$P$921,"va") -> 59.35 | F7: =AVERAGE(Data!$B$2:$B$921) -> 53.51087
A8: Mean Resting BP [mm Hg] (excl. 0 placeholders) | B8: =IFERROR(AVERAGEIFS(Data!$E$2:$E$921,Data!$P$2:$P$921,"cleveland",Data!$E$2:$E$921,">0"),"n/a") -> 131.68977 | C8: =IFERROR(AVERAGEIFS(Data!$E$2:$E$921,Data!$P$2:$P$921,"hungarian",Data!$E$2:$E$921,">0"),"n/a") -> 132.58362 | D8: =IFERROR(AVERAGEIFS(Data!$E$2:$E$921,Data!$P$2:$P$921,"switzerland",Data!$E$2:$E$921,">0"),"n/a") -> 130.20661 | E8: =IFERROR(AVERAGEIFS(Data!$E$2:$E$921,Data!$P$2:$P$921,"va",Data!$E$2:$E$921,">0"),"n/a") -> 134.6993 | F8: =AVERAGEIF(Data!$E$2:$E$921,">0") -> 132.28605
A9: Mean Serum Cholesterol [mg/dL] (excl. 0 placeholders) | B9: =IFERROR(AVERAGEIFS(Data!$F$2:$F$921,Data!$P$2:$P$921,"cleveland",Data!$F$2:$F$921,">0"),"n/a") -> 246.69307 | C9: =IFERROR(AVERAGEIFS(Data!$F$2:$F$921,Data!$P$2:$P$921,"hungarian",Data!$F$2:$F$921,">0"),"n/a") -> 250.84871 | D9: =IFERROR(AVERAGEIFS(Data!$F$2:$F$921,Data!$P$2:$P$921,"switzerland",Data!$F$2:$F$921,">0"),"n/a") -> n/a | E9: =IFERROR(AVERAGEIFS(Data!$F$2:$F$921,Data!$P$2:$P$921,"va",Data!$F$2:$F$921,">0"),"n/a") -> 239.56944 | F9: =AVERAGEIF(Data!$F$2:$F$921,">0") -> 246.83287
A10: Mean Max Heart Rate [bpm] | B10: =AVERAGEIFS(Data!$I$2:$I$921,Data!$P$2:$P$921,"cleveland") -> 149.60726 | C10: =AVERAGEIFS(Data!$I$2:$I$921,Data!$P$2:$P$921,"hungarian") -> 139.12969 | D10: =AVERAGEIFS(Data!$I$2:$I$921,Data!$P$2:$P$921,"switzerland") -> 121.55738 | E10: =AVERAGEIFS(Data!$I$2:$I$921,Data!$P$2:$P$921,"va") -> 122.79592 | F10: =AVERAGE(Data!$I$2:$I$921) -> 137.54566
A11: Mean ST Depression [mm] | B11: =AVERAGEIFS(Data!$K$2:$K$921,Data!$P$2:$P$921,"cleveland") -> 1.039604 | C11: =AVERAGEIFS(Data!$K$2:$K$921,Data!$P$2:$P$921,"hungarian") -> 0.58605442 | D11: =AVERAGEIFS(Data!$K$2:$K$921,Data!$P$2:$P$921,"switzerland") -> 0.65384615 | E11: =AVERAGEIFS(Data!$K$2:$K$921,Data!$P$2:$P$921,"va") -> 1.3208333 | F11: =AVERAGE(Data!$K$2:$K$921) -> 0.87878788
A13: Missing values per field
A14: Age (age) | B14: =COUNTIFS(Data!$P$2:$P$921,"cleveland",Data!$B$2:$B$921,"") -> 0 | C14: =COUNTIFS(Data!$P$2:$P$921,"hungarian",Data!$B$2:$B$921,"") -> 0 | D14: =COUNTIFS(Data!$P$2:$P$921,"switzerland",Data!$B$2:$B$921,"") -> 0 | E14: =COUNTIFS(Data!$P$2:$P$921,"va",Data!$B$2:$B$921,"") -> 0 | F14: =COUNTBLANK(Data!$B$2:$B$921) -> 0
A15: Sex (sex) | B15: =COUNTIFS(Data!$P$2:$P$921,"cleveland",Data!$C$2:$C$921,"") -> 0 | C15: =COUNTIFS(Data!$P$2:$P$921,"hungarian",Data!$C$2:$C$921,"") -> 0 | D15: =COUNTIFS(Data!$P$2:$P$921,"switzerland",Data!$C$2:$C$921,"") -> 0 | E15: =COUNTIFS(Data!$P$2:$P$921,"va",Data!$C$2:$C$921,"") -> 0 | F15: =COUNTBLANK(Data!$C$2:$C$921) -> 0
A16: Chest Pain Type (cp) | B16: =COUNTIFS(Data!$P$2:$P$921,"cleveland",Data!$D$2:$D$921,"") -> 0 | C16: =COUNTIFS(Data!$P$2:$P$921,"hungarian",Data!$D$2:$D$921,"") -> 0 | D16: =COUNTIFS(Data!$P$2:$P$921,"switzerland",Data!$D$2:$D$921,"") -> 0 | E16: =COUNTIFS(Data!$P$2:$P$921,"va",Data!$D$2:$D$921,"") -> 0 | F16: =COUNTBLANK(Data!$D$2:$D$921) -> 0
A17: Resting BP (trestbps) | B17: =COUNTIFS(Data!$P$2:$P$921,"cleveland",Data!$E$2:$E$921,"") -> 0 | C17: =COUNTIFS(Data!$P$2:$P$921,"hungarian",Data!$E$2:$E$921,"") -> 1 | D17: =COUNTIFS(Data!$P$2:$P$921,"switzerland",Data!$E$2:$E$921,"") -> 2 | E17: =COUNTIFS(Data!$P$2:$P$921,"va",Data!$E$2:$E$921,"") -> 56 | F17: =COUNTBLANK(Data!$E$2:$E$921) -> 59
A18: Serum Cholesterol (chol) | B18: =COUNTIFS(Data!$P$2:$P$921,"cleveland",Data!$F$2:$F$921,"") -> 0 | C18: =COUNTIFS(Data!$P$2:$P$921,"hungarian",Data!$F$2:$F$921,"") -> 23 | D18: =COUNTIFS(Data!$P$2:$P$921,"switzerland",Data!$F$2:$F$921,"") -> 0 | E18: =COUNTIFS(Data!$P$2:$P$921,"va",Data!$F$2:$F$921,"") -> 7 | F18: =COUNTBLANK(Data!$F$2:$F$921) -> 30
A19: Fasting Blood Sugar >120 (fbs) | B19: =COUNTIFS(Data!$P$2:$P$921,"cleveland",Data!$G$2:$G$921,"") -> 0 | C19: =COUNTIFS(Data!$P$2:$P$921,"hungarian",Data!$G$2:$G$921,"") -> 8 | D19: =COUNTIFS(Data!$P$2:$P$921,"switzerland",Data!$G$2:$G$921,"") -> 75 | E19: =COUNTIFS(Data!$P$2:$P$921,"va",Data!$G$2:$G$921,"") -> 7 | F19: =COUNTBLANK(Data!$G$2:$G$921) -> 90
A20: Resting ECG (restecg) | B20: =COUNTIFS(Data!$P$2:$P$921,"cleveland",Data!$H$2:$H$921,"") -> 0 | C20: =COUNTIFS(Data!$P$2:$P$921,"hungarian",Data!$H$2:$H$921,"") -> 1 | D20: =COUNTIFS(Data!$P$2:$P$921,"switzerland",Data!$H$2:$H$921,"") -> 1 | E20: =COUNTIFS(Data!$P$2:$P$921,"va",Data!$H$2:$H$921,"") -> 0 | F20: =COUNTBLANK(Data!$H$2:$H$921) -> 2
A21: Max Heart Rate (thalach) | B21: =COUNTIFS(Data!$P$2:$P$921,"cleveland",Data!$I$2:$I$921,"") -> 0 | C21: =COUNTIFS(Data!$P$2:$P$921,"hungarian",Data!$I$2:$I$921,"") -> 1 | D21: =COUNTIFS(Data!$P$2:$P$921,"switzerland",Data!$I$2:$I$921,"") -> 1 | E21: =COUNTIFS(Data!$P$2:$P$921,"va",Data!$I$2:$I$921,"") -> 53 | F21: =COUNTBLANK(Data!$I$2:$I$921) -> 55
A22: Exercise-Induced Angina (exang) | B22: =COUNTIFS(Data!$P$2:$P$921,"cleveland",Data!$J$2:$J$921,"") -> 0 | C22: =COUNTIFS(Data!$P$2:$P$921,"hungarian",Data!$J$2:$J$921,"") -> 1 | D22: =COUNTIFS(Data!$P$2:$P$921,"switzerland",Data!$J$2:$J$921,"") -> 1 | E22: =COUNTIFS(Data!$P$2:$P$921,"va",Data!$J$2:$J$921,"") -> 53 | F22: =COUNTBLANK(Data!$J$2:$J$921) -> 55
A23: ST Depression (oldpeak) | B23: =COUNTIFS(Data!$P$2:$P$921,"cleveland",Data!$K$2:$K$921,"") -> 0 | C23: =COUNTIFS(Data!$P$2:$P$921,"hungarian",Data!$K$2:$K$921,"") -> 0 | D23: =COUNTIFS(Data!$P$2:$P$921,"switzerland",Data!$K$2:$K$921,"") -> 6 | E23: =COUNTIFS(Data!$P$2:$P$921,"va",Data!$K$2:$K$921,"") -> 56 | F23: =COUNTBLANK(Data!$K$2:$K$921) -> 62
A24: ST Slope (slope) | B24: =COUNTIFS(Data!$P$2:$P$921,"cleveland",Data!$L$2:$L$921,"") -> 0 | C24: =COUNTIFS(Data!$P$2:$P$921,"hungarian",Data!$L$2:$L$921,"") -> 190 | D24: =COUNTIFS(Data!$P$2:$P$921,"switzerland",Data!$L$2:$L$921,"") -> 17 | E24: =COUNTIFS(Data!$P$2:$P$921,"va",Data!$L$2:$L$921,"") -> 102 | F24: =COUNTBLANK(Data!$L$2:$L$921) -> 309
A25: Major Vessels (Fluoroscopy) (ca) | B25: =COUNTIFS(Data!$P$2:$P$921,"cleveland",Data!$M$2:$M$921,"") -> 4 | C25: =COUNTIFS(Data!$P$2:$P$921,"hungarian",Data!$M$2:$M$921,"") -> 290 | D25: =COUNTIFS(Data!$P$2:$P$921,"switzerland",Data!$M$2:$M$921,"") -> 118 | E25: =COUNTIFS(Data!$P$2:$P$921,"va",Data!$M$2:$M$921,"") -> 198 | F25: =COUNTBLANK(Data!$M$2:$M$921) -> 610
A26: Thallium Stress Test (thal) | B26: =COUNTIFS(Data!$P$2:$P$921,"cleveland",Data!$N$2:$N$921,"") -> 2 | C26: =COUNTIFS(Data!$P$2:$P$921,"hungarian",Data!$N$2:$N$921,"") -> 266 | D26: =COUNTIFS(Data!$P$2:$P$921,"switzerland",Data!$N$2:$N$921,"") -> 52 | E26: =COUNTIFS(Data!$P$2:$P$921,"va",Data!$N$2:$N$921,"") -> 166 | F26: =COUNTBLANK(Data!$N$2:$N$921) -> 486
A27: Diagnosis (num) (target) | B27: =COUNTIFS(Data!$P$2:$P$921,"cleveland",Data!$O$2:$O$921,"") -> 0 | C27: =COUNTIFS(Data!$P$2:$P$921,"hungarian",Data!$O$2:$O$921,"") -> 0 | D27: =COUNTIFS(Data!$P$2:$P$921,"switzerland",Data!$O$2:$O$921,"") -> 0 | E27: =COUNTIFS(Data!$P$2:$P$921,"va",Data!$O$2:$O$921,"") -> 0 | F27: =COUNTBLANK(Data!$O$2:$O$921) -> 0
